Traceback (most recent call last):
  File "C:\Users\pc\AppData\Local\Programs\Python\Python310\lib\site-packages\jupyter_cache\executors\utils.py", line 58, in single_nb_execution
    executenb(
  File "C:\Users\pc\AppData\Local\Programs\Python\Python310\lib\site-packages\nbclient\client.py", line 1314, in execute
    return NotebookClient(nb=nb, resources=resources, km=km, **kwargs).execute()
  File "C:\Users\pc\AppData\Local\Programs\Python\Python310\lib\site-packages\jupyter_core\utils\__init__.py", line 165, in wrapped
    return loop.run_until_complete(inner)
  File "C:\Users\pc\AppData\Local\Programs\Python\Python310\lib\asyncio\base_events.py", line 646, in run_until_complete
    return future.result()
  File "C:\Users\pc\AppData\Local\Programs\Python\Python310\lib\site-packages\nbclient\client.py", line 709, in async_execute
    await self.async_execute_cell(
  File "C:\Users\pc\AppData\Local\Programs\Python\Python310\lib\site-packages\nbclient\client.py", line 1062, in async_execute_cell
    await self._check_raise_for_error(cell, cell_index, exec_reply)
  File "C:\Users\pc\AppData\Local\Programs\Python\Python310\lib\site-packages\nbclient\client.py", line 918, in _check_raise_for_error
    raise CellExecutionError.from_cell_and_msg(cell, exec_reply_content)
nbclient.exceptions.CellExecutionError: An error occurred while executing the following cell:
------------------
import pandas as pd
import cv2
import numpy as np
import requests
from PIL import Image
from io import BytesIO
import matplotlib.pyplot as plt
from sklearn.model_selection import train_test_split
from tqdm.notebook import tqdm
import os



carpetas_path = "/kaggle/input/flores-uninorte"

datos_aves = []
for carpeta in os.listdir(carpetas_path):
    path = f"{carpetas_path}/{carpeta}/"
    for element in os.listdir(path):
        df = pd.read_csv(f"{carpetas_path}/{carpeta}/{element}")
        datos_aves.append(df)
        
df_final = pd.concat(datos_aves, axis = 0).reset_index(drop = True)
------------------


[1;31m--------------------------------------------------------------------------[0m
[1;31mFileNotFoundError[0m                        Traceback (most recent call last)
Cell [1;32mIn [1], line 17[0m
[0;32m     14[0m carpetas_path [38;5;241m=[39m [38;5;124m"[39m[38;5;124m/kaggle/input/flores-uninorte[39m[38;5;124m"[39m
[0;32m     16[0m datos_aves [38;5;241m=[39m []
[1;32m---> 17[0m [38;5;28;01mfor[39;00m carpeta [38;5;129;01min[39;00m os[38;5;241m.[39mlistdir(carpetas_path):
[0;32m     18[0m     path [38;5;241m=[39m [38;5;124mf[39m[38;5;124m"[39m[38;5;132;01m{[39;00mcarpetas_path[38;5;132;01m}[39;00m[38;5;124m/[39m[38;5;132;01m{[39;00mcarpeta[38;5;132;01m}[39;00m[38;5;124m/[39m[38;5;124m"[39m
[0;32m     19[0m     [38;5;28;01mfor[39;00m element [38;5;129;01min[39;00m os[38;5;241m.[39mlistdir(path):

[1;31mFileNotFoundError[0m: [WinError 3] El sistema no puede encontrar la ruta especificada: '/kaggle/input/flores-uninorte'

